scripts/test_case15.txt
40
0 o
1 o
2 o
3 o
4 o
5 o
6 o
7 o
8 o
9 o
10 o
11 o
12 o
13 o
14 o
15 o
16 o
17 o
18 o
19 o
20 o
21 o
22 o
23 o
24 o
25 o
26 o
27 o
28 o
29 o
30 o
31 o
32 o
33 o
34 o
35 o
36 o
37 o
38 o
39 o
.
35 B 45715488 MSFT 49858 7133
37 S 86897210 AAPL 25215 538
38 S 42611780 AAPL 35847 6635
39 S 91232816 MSFT 48798 8591
38 S 77394562 GOOG 83716 1670
39 S 63694894 MSFT 23750 4324
39 B 26304126 AAPL 43756 6392
37 B 2469851 GOOG 24862 2845
39 C 63694894
38 S 60391581 GOOG 88170 6826
38 S 19185610 MSFT 81099 3171
39 C 91232816
39 C 91232816
39 B 90384806 MSFT 97036 7638
38 B 2170322 GOOG 18171 1163
37 B 32488934 AMZN 70663 8647
39 C 63694894
38 S 1582834 AMZN 25584 8880
38 S 15614912 GOOG 45974 355
39 B 76453129 AAPL 94833 8309
38 B 34493209 MSFT 91944 3272
38 B 76225544 MSFT 76564 4250
39 S 8455138 AMZN 19472 2509
39 B 33301352 MSFT 9719 324
39 B 45390171 MSFT 3644 6209
38 S 73322034 GOOG 23198 7745
39 B 79745017 GOOG 78130 919
39 S 8160585 AMZN 82079 2925
39 S 271154 AMZN 45743 4566
36 B 27527815 AMZN 41736 2958
38 B 78858025 AAPL 13697 4331
36 C 27527815
36 B 16313742 AAPL 19745 3208
39 B 63277387 AAPL 35212 6332
39 C 63277387
39 C 79745017
39 C 271154
38 B 30696601 GOOG 77842 8829
35 S 85398666 AMZN 46970 9055
39 B 47485553 MSFT 16062 1522
39 B 80103934 AMZN 58777 3307
38 B 39182964 AAPL 64997 6005
37 C 2469851
35 B 50369957 GOOG 4062 5901
34 S 45338304 GOOG 53526 1032
38 C 39182964
36 B 7158209 AMZN 77286 1430
39 B 99227893 AMZN 59846 2720
39 B 33031305 GOOG 73808 3276
39 S 25279369 AMZN 81021 8238
39 C 271154
38 C 15614912
38 B 62269724 AMZN 80648 7538
35 B 19071897 AAPL 9808 1470
38 C 15614912
39 B 56546393 MSFT 67043 2258
36 S 97925885 MSFT 27304 430
35 S 20530073 GOOG 61834 5013
37 C 32488934
37 S 47002204 AAPL 92112 206
38 S 17093609 AAPL 42846 4890
38 S 31749104 GOOG 10974 8788
38 B 50619669 AMZN 83204 6505
39 S 92714360 AMZN 8251 529
38 B 84138816 AAPL 53391 1428
38 C 84138816
37 S 51474688 GOOG 62950 3836
38 S 68802832 GOOG 34252 8629
36 S 20608978 AMZN 44843 3032
39 S 39881931 AMZN 5116 9427
36 S 49093004 AAPL 25050 3833
38 S 35610394 AAPL 26628 9193
39 S 54095530 AMZN 68319 110
38 S 75807361 AMZN 98944 3694
39 C 33301352
38 S 90050695 GOOG 94660 3828
39 B 43097592 AAPL 34633 8948
37 C 86897210
39 S 98683863 AAPL 93472 7431
39 C 79745017
39 S 75904414 MSFT 86319 3742
38 B 67591842 AMZN 44967 2063
38 C 50619669
38 C 34493209
39 C 75904414
38 C 75807361
39 B 75600679 AMZN 16160 7313
38 C 17093609
39 S 82489337 AAPL 30487 1721
39 B 53183254 AAPL 84462 8964
38 B 79711769 GOOG 63802 4848
37 C 2469851
38 C 42611780
39 C 54095530
37 B 24533423 GOOG 45656 6017
38 S 1620327 AAPL 72637 7236
39 C 90384806
37 S 55846063 AAPL 69362 1653
38 C 42611780
38 S 34385621 MSFT 95271 9558
38 C 31749104
39 C 75904414
37 B 34738718 MSFT 9980 8415
39 C 56546393
38 C 67591842
39 B 10542061 AMZN 73170 9499
39 B 4249917 AAPL 29055 4298
39 C 99227893
39 S 65974087 AAPL 46976 674
39 S 13958904 GOOG 19532 2492
39 S 53907203 GOOG 12452 8902
38 S 20919677 GOOG 34422 1849
39 C 47485553
38 C 19185610
38 S 20487509 AAPL 12620 3772
39 S 69957297 AMZN 61397 697
39 C 53183254
39 C 43097592
39 B 43093181 GOOG 20077 3748
39 B 56597133 GOOG 64426 7678
38 B 6018045 GOOG 55276 7208
39 B 3500563 AAPL 50162 5327
39 S 77169049 AMZN 28440 8619
37 C 32488934
38 B 67789640 AMZN 17617 3668
39 S 15534577 GOOG 72385 1168
36 C 49093004
38 C 50619669
37 C 32488934
38 C 78858025
38 B 69819598 AMZN 38841 258
39 B 16574129 AAPL 29977 2513
36 B 42521847 AAPL 98733 1001
38 S 91646697 GOOG 61485 4265
38 B 55735093 AMZN 80116 5737
39 B 69563358 MSFT 70270 6044
37 C 2469851
33 S 67778062 MSFT 16573 2737
38 B 92482221 GOOG 69648 9621
39 C 69957297
37 C 51474688
36 S 6082459 MSFT 75257 7283
37 S 62247428 AMZN 32561 9437
38 B 72828950 AMZN 89194 4543
37 B 19018696 AAPL 13975 5980
36 C 97925885
39 C 45390171
39 S 95140470 AAPL 76384 3072
39 C 10542061
39 B 97356129 GOOG 31951 9347
39 S 36953436 AMZN 62706 2032
39 S 31115335 GOOG 34875 9873
39 S 69489793 GOOG 94841 3870
36 C 49093004
39 S 5184574 GOOG 94790 6265
38 S 12440422 GOOG 15391 2443
39 C 8455138
38 B 17948870 GOOG 7537 8335
39 C 92714360
39 C 53907203
38 C 68802832
39 B 44413934 AMZN 44465 2935
38 S 1873288 AAPL 34224 4747
38 S 38409942 GOOG 12788 9891
39 S 35825021 AMZN 4779 171
39 S 97987659 GOOG 80193 5149
39 C 36953436
39 C 45390171
39 S 31055516 AMZN 33009 1091
38 C 19185610
31 B 88402293 MSFT 58926 4092
39 S 32140902 AAPL 24578 5793
39 B 30492461 GOOG 79812 3205
39 B 88433524 MSFT 59314 8139
39 B 95503915 GOOG 66776 2241
37 B 37956940 GOOG 1824 7993
39 S 18442867 AAPL 46580 2709
37 S 95409183 AMZN 76791 6696
39 B 15897541 MSFT 82405 9580
39 C 77169049
38 S 12211882 AAPL 34773 1480
38 B 70233951 GOOG 76894 7007
39 S 82587 MSFT 72236 7040
37 C 32488934
35 B 30122665 AAPL 67254 3648
30 S 50752403 AMZN 90140 3249
39 B 85126250 MSFT 7671 9927
34 C 45338304
36 S 56124798 MSFT 44747 3945
36 S 94177635 GOOG 96368 9062
38 S 8214949 GOOG 94051 9722
38 S 8772730 MSFT 80279 6169
39 S 77566836 AMZN 71647 3383
38 S 5310379 AMZN 23439 4973
37 S 90282289 AAPL 33009 1048
36 B 30531081 AAPL 82098 1720
38 C 60391581
39 B 88987197 AAPL 88075 4895
37 C 2469851
39 S 55850065 AMZN 87415 1410
39 S 85610216 AAPL 51027 4491
38 C 12440422
39 B 69060482 AAPL 3788 2343
38 S 69667682 AMZN 92342 9487
39 B 4049093 AMZN 1256 6065
38 B 16230583 MSFT 93884 1953
38 B 32217192 AMZN 21241 3910
39 S 54942939 MSFT 23485 7120
39 C 39881931
36 B 14652883 GOOG 65948 2582
39 C 4249917
38 B 56437603 MSFT 66446 6757
37 S 13014822 MSFT 75205 3726
38 C 91646697
38 S 97871843 GOOG 31830 7808
38 S 39064788 AMZN 2096 2671
35 B 49799840 AMZN 35548 1627
35 S 55933765 AMZN 69954 8030
36 S 53981368 AAPL 65450 9241
39 S 2348833 AMZN 30341 1156
39 C 53907203
39 B 70371779 GOOG 51710 5489
38 S 94535056 MSFT 17425 3418
37 B 10408067 AMZN 91594 6362
37 B 57217820 AMZN 89291 8500
39 B 72378918 AMZN 10516 9675
38 S 32646687 AMZN 70787 9932
38 B 76905169 AMZN 39698 2892
38 S 4828866 AAPL 52967 9398
38 S 57676457 GOOG 7188 6736
36 S 97803986 AMZN 19723 1826
33 C 67778062
38 S 90686844 AAPL 7438 9836
36 B 67864584 AAPL 69588 3275
32 S 57198038 AMZN 3355 3625
37 C 55846063
37 S 22065956 MSFT 43921 7403
38 B 16351295 AAPL 53078 9703
38 S 97581828 GOOG 53038 2938
38 S 30701443 MSFT 30071 4068
36 S 95424255 MSFT 27964 8935
36 B 70013958 AMZN 1155 8706
38 S 61865324 GOOG 89932 2121
37 S 47768399 GOOG 71828 7358
38 C 57676457
34 S 92089825 MSFT 80538 5801
34 S 59050674 MSFT 83870 2799
37 B 67021247 AMZN 57782 2256
36 C 49093004
37 S 58488333 GOOG 75854 9426
37 S 56610769 GOOG 32099 9266
38 S 57051477 GOOG 66572 2844
38 B 34622506 AAPL 82150 8410
38 B 78177739 AAPL 20724 681
37 S 19114878 AAPL 38445 8446
38 B 56444072 GOOG 18849 2475
38 B 54850709 AAPL 50294 368
38 S 33453611 MSFT 50066 8147
35 B 13113074 MSFT 38299 3961
38 B 6498378 GOOG 18215 4699
38 B 74579730 AMZN 83505 9852
37 S 96434852 AAPL 32986 2177
37 B 74574514 GOOG 65499 1286
38 S 15824333 GOOG 89390 4500
37 S 99871287 AMZN 36899 8725
37 S 13877687 AAPL 3976 6487
36 C 30531081
38 B 64342130 GOOG 65490 8336
38 C 77394562
34 S 67025771 GOOG 79452 9168
37 S 49428894 AAPL 94098 6013
38 C 17093609
38 S 98832929 GOOG 21827 1983
35 C 30122665
37 B 26894196 GOOG 36071 3513
38 C 30701443
34 C 92089825
38 S 91395679 AAPL 1724 2602
37 S 81510737 AAPL 94163 3244
38 B 13240996 AMZN 92453 858
38 C 61865324
38 C 50619669
38 S 88206543 GOOG 80839 8905
36 S 62363323 GOOG 26078 6991
37 C 62247428
37 S 14884789 GOOG 50978 8812
36 B 56351256 MSFT 44313 7334
35 B 25233264 GOOG 10171 9164
37 S 61968877 GOOG 54699 9775
37 B 72083402 GOOG 1538 805
36 B 53594297 GOOG 21437 8390
36 S 7288227 MSFT 47740 899
37 S 37177734 MSFT 11119 3576
37 S 34125918 AAPL 94548 3986
37 C 74574514
37 B 87955777 GOOG 82722 8026
36 S 36719222 AAPL 61573 7193
36 S 8508585 AAPL 69798 9785
37 C 24533423
37 C 32488934
37 B 70527692 GOOG 72510 8703
37 C 56610769
32 C 57198038
37 C 13877687
37 S 88467976 GOOG 67837 3193
35 C 13113074
37 B 67301558 AAPL 67563 7666
37 S 96674852 AMZN 8336 5441
37 C 58488333
36 C 53981368
