scripts/test_case2.txt
40
0 o
1 o
2 o
3 o
4 o
5 o
6 o
7 o
8 o
9 o
10 o
11 o
12 o
13 o
14 o
15 o
16 o
17 o
18 o
19 o
20 o
21 o
22 o
23 o
24 o
25 o
26 o
27 o
28 o
29 o
30 o
31 o
32 o
33 o
34 o
35 o
36 o
37 o
38 o
39 o
.
39 B 33968324 GOOG 42277 8171
37 B 32838694 AAPL 35929 1068
39 B 81227942 GOOG 24117 4621
37 S 71900058 MSFT 51762 7173
38 B 5516285 AAPL 79343 7801
39 C 81227942
38 S 98181765 GOOG 32516 5954
39 C 33968324
37 C 32838694
37 B 99382092 AMZN 83794 830
38 S 1115678 AMZN 30033 106
39 B 10284825 AAPL 80020 1759
37 S 99507468 MSFT 22393 9639
39 B 8150937 MSFT 92451 7060
36 S 41074699 AMZN 62678 6059
38 S 70937966 MSFT 94210 7578
38 B 9381924 GOOG 45436 6447
37 C 99382092
38 B 57822107 MSFT 74838 9636
39 B 20262517 GOOG 18545 6102
39 S 95847331 AMZN 23477 992
39 C 8150937
39 C 20262517
37 C 71900058
39 B 81148222 AAPL 83013 7559
39 B 63883919 GOOG 6335 6295
39 B 25651749 AMZN 31118 7971
39 S 8382892 GOOG 52388 4588
39 S 56440090 GOOG 1052 9368
38 C 1115678
39 S 87646167 GOOG 42894 5420
38 S 80267142 MSFT 52202 8327
39 C 63883919
39 S 40621965 AAPL 2813 4457
39 B 97021461 AAPL 97900 4561
39 B 21925938 GOOG 74939 9855
36 B 31992284 GOOG 98496 292
38 B 33737259 GOOG 63264 7199
38 B 19515189 GOOG 23403 8338
38 B 97204917 GOOG 16786 6814
38 B 65988044 AAPL 8346 9910
39 C 81148222
38 S 3092177 GOOG 14965 4895
38 B 3282603 AMZN 83364 4607
39 B 75185583 MSFT 61519 8877
35 S 35457940 GOOG 72457 8839
39 B 39594799 AMZN 18559 6555
39 S 89702468 GOOG 13640 1246
35 S 61399437 AAPL 39855 6046
37 S 42237260 AMZN 80982 4331
37 B 9731479 AAPL 6606 2527
38 C 3092177
39 C 87646167
39 S 48856066 AAPL 26299 8244
38 S 251723 AAPL 42895 1232
39 S 27914348 AAPL 74636 6623
39 B 22884249 AMZN 82974 7821
38 C 97204917
38 C 65988044
39 C 8382892
39 S 15010805 GOOG 5272 8898
37 S 81399947 AAPL 5328 1257
38 B 56437146 MSFT 60413 8652
37 B 46779198 MSFT 65324 7156
39 S 66451456 MSFT 6423 1308
39 S 73161895 MSFT 54110 167
33 S 77482752 AAPL 21752 8644
33 B 26250840 AAPL 58987 1141
39 B 85785152 GOOG 57115 7968
39 B 75040484 AMZN 39064 9867
38 B 83507311 GOOG 4534 2987
39 S 14301294 MSFT 93474 4545
39 S 23757551 MSFT 68677 4218
39 C 75185583
39 S 43188510 MSFT 16734 5040
39 C 66451456
39 S 94967807 AAPL 73977 2724
39 B 62176604 GOOG 90113 6114
34 B 4312870 AMZN 28827 5962
39 C 75040484
39 C 10284825
39 C 8382892
39 B 90621565 AAPL 54520 8116
39 C 10284825
39 S 99017349 AMZN 50925 3785
38 B 27493500 AMZN 13256 8460
39 S 55030098 AAPL 48387 4006
39 C 43188510
37 B 68958722 MSFT 49050 5486
37 B 39700733 AAPL 34555 571
39 S 42219440 AMZN 27311 5663
39 C 75040484
39 S 82795119 AAPL 32201 6825
39 B 39737939 AMZN 96453 3814
39 S 20568558 AMZN 15672 292
39 C 97021461
39 C 23757551
39 B 13355380 AMZN 59299 6426
39 C 94967807
38 B 18093974 MSFT 23119 7017
37 B 28031260 MSFT 53656 7043
39 B 98794762 AAPL 15239 2522
38 B 69826973 AAPL 70165 3453
37 C 81399947
37 C 68958722
36 C 31992284
39 B 81020698 MSFT 82461 9970
39 S 96528021 AAPL 78315 6369
37 C 28031260
38 S 64103021 AMZN 8519 4656
39 S 33168343 AAPL 4052 5883
38 S 36786244 GOOG 15496 9336
38 C 69826973
38 C 3282603
37 C 39700733
37 C 81399947
39 S 62990596 MSFT 44575 2676
37 C 46779198
39 S 71435959 GOOG 85377 2086
39 C 96528021
37 C 28031260
39 B 99538783 AMZN 67457 8023
35 S 93835906 MSFT 70123 2940
39 B 36691183 AAPL 41087 2077
37 S 36570613 GOOG 18429 1173
39 C 33168343
39 S 20671444 AAPL 20340 1062
39 S 53541360 AAPL 25364 926
39 S 48037105 GOOG 36169 1636
39 B 17739654 MSFT 76624 3337
38 B 34836016 AAPL 58022 7931
39 B 67980717 GOOG 53142 5156
39 C 39594799
35 B 57858097 MSFT 65600 5936
39 S 32402873 MSFT 5416 8504
39 B 80877796 AMZN 91192 7334
39 S 44661209 AAPL 97425 4551
37 S 58744374 GOOG 21403 9241
38 B 63349549 MSFT 2622 464
39 C 20671444
30 S 14558240 AAPL 64403 4591
37 S 97258014 AAPL 41904 5160
39 B 7996981 MSFT 48780 6808
39 B 88280381 AMZN 90175 9063
38 B 69259546 AAPL 65797 7894
39 C 99538783
38 C 56437146
38 S 54744345 AAPL 86983 2425
39 B 15080364 AMZN 64976 1474
34 B 1351901 AAPL 41262 35
39 B 25601127 GOOG 48267 8285
39 B 5810090 AAPL 83454 592
38 C 33737259
34 C 4312870
38 C 63349549
38 C 57822107
39 S 9640069 AAPL 53110 6617
39 C 39594799
37 S 1129198 AAPL 35996 2757
39 S 60371090 AMZN 71824 9637
38 B 3772617 AAPL 85514 9873
37 C 32838694
39 B 94050992 AAPL 57432 1276
38 B 57350417 GOOG 21535 6847
38 B 74446017 GOOG 34706 4434
37 C 1129198
39 C 8382892
39 B 75273121 AMZN 75431 6925
39 C 20671444
38 C 74446017
39 B 32351531 MSFT 5003 3999
38 C 5516285
39 S 60210965 AMZN 51781 7089
38 B 66918179 MSFT 59630 8769
37 S 65630610 MSFT 80782 4950
38 S 17639296 GOOG 14776 7370
39 S 64828697 MSFT 92072 2065
39 C 81020698
36 S 10357339 AMZN 4727 9001
39 C 33968324
37 S 70911847 AAPL 70987 2262
39 S 54072650 GOOG 50702 9533
37 C 32838694
39 B 71878578 AMZN 68491 3441
39 C 66451456
36 C 41074699
39 C 8382892
38 S 90509131 GOOG 81770 4198
38 B 96252774 MSFT 83147 8450
38 C 1115678
37 B 44787647 AAPL 83707 624
38 C 34836016
38 B 9534176 AAPL 2831 9215
35 S 13561196 GOOG 86572 7063
38 B 55327817 GOOG 78998 9274
38 C 57350417
37 S 74990977 MSFT 48220 9521
38 S 40570486 GOOG 46881 5902
37 C 46779198
36 C 31992284
37 S 7504528 MSFT 85410 6156
37 B 37427670 AMZN 37658 4595
29 B 24431907 AMZN 76139 8774
38 S 40190256 MSFT 58861 1176
37 B 1359748 AMZN 88427 2977
38 B 42819923 AAPL 8925 1554
37 C 36570613
36 C 41074699
38 S 30405873 AAPL 78236 5820
38 C 18093974
38 B 89265533 AMZN 54453 9960
38 B 83913856 AMZN 84393 5289
35 C 13561196
38 S 91845272 AMZN 26420 7054
34 S 12398115 MSFT 97087 1720
36 S 37642839 MSFT 79330 4242
37 B 24523344 GOOG 64144 7622
38 C 66918179
35 C 35457940
32 S 83451167 GOOG 28448 168
38 B 95477444 MSFT 30986 2775
34 S 90839306 AAPL 86629 8236
37 C 1359748
38 C 56437146
36 S 82849558 MSFT 94978 9075
37 C 68958722
38 B 74797490 MSFT 75803 534
37 B 68214630 AMZN 51371 8931
36 B 89091064 AMZN 45659 2427
38 B 76529266 GOOG 72910 9968
38 S 17056754 AMZN 10625 5251
37 B 78981684 AAPL 96020 1838
38 S 38890563 MSFT 82509 5249
38 B 81224707 MSFT 80652 9744
37 S 17997159 MSFT 37169 1705
27 S 58281766 AMZN 30289 9084
38 B 95429060 AMZN 66604 9638
38 C 56437146
36 C 82849558
38 S 61860272 GOOG 66202 8154
38 B 2535019 AAPL 16131 39
37 C 1129198
35 C 61399437
38 B 29472897 AAPL 97493 6662
36 C 10357339
35 C 93835906
38 C 3092177
37 C 1359748
38 B 63719239 AMZN 3664 8246
38 B 88274912 MSFT 73828 8924
38 C 40190256
38 C 9534176
37 S 44258472 AMZN 55028 6726
37 C 9731479
38 S 34524790 AAPL 86762 7160
36 B 25980882 GOOG 34677 3338
37 B 20679907 AAPL 20157 2197
38 B 26417043 GOOG 77431 9872
38 B 29013306 AMZN 25275 2223
36 B 32131124 GOOG 96222 1451
38 S 70283167 GOOG 78103 4340
37 C 65630610
38 C 29013306
38 S 46523189 AMZN 90753 5519
38 B 9739986 AAPL 10920 1322
36 S 44971488 GOOG 95059 737
37 B 42762234 AMZN 59940 931
34 B 14492689 GOOG 59478 4269
38 B 62371083 AAPL 17454 6878
37 C 24523344
36 S 63179328 AMZN 6415 2895
38 B 65882799 AAPL 15298 1643
38 C 65882799
38 B 4983674 MSFT 29135 7130
38 C 90509131
38 B 21654179 GOOG 87501 6656
36 B 87379133 GOOG 51254 3887
37 S 3660685 AMZN 32266 4322
38 B 53305170 GOOG 55570 864
37 S 69976769 GOOG 36065 622
37 B 84831251 AMZN 49905 1686
33 C 26250840
38 C 96252774
38 S 59997605 AMZN 8475 1053
36 B 6317566 AAPL 97983 659
38 C 59997605
36 S 59515606 GOOG 28343 4202
38 C 63349549
36 C 25980882
38 S 59850036 AMZN 75946 1555
36 B 60741310 AAPL 48369 5598
36 C 41074699
36 B 85670230 GOOG 63749 5026
37 C 84831251
35 B 89770005 GOOG 15649 4449
36 C 25980882
38 S 67858786 AMZN 89881 972
37 B 96531181 GOOG 69868 948
37 S 54621532 AMZN 53873 7154
38 S 82327172 AMZN 72880 6295
38 S 46961842 AMZN 8488 9508
38 S 8925705 MSFT 19328 7376
38 B 78372189 GOOG 27636 3916
37 B 68556509 MSFT 16667 7163
36 S 20549503 AMZN 68715 6976
38 C 66918179
37 C 39700733
37 B 70919985 GOOG 69751 6458
36 C 89091064
37 S 59093065 AMZN 45847 6233
36 C 63179328
37 C 17997159
37 B 55728878 AMZN 32348 7258
37 S 97961520 MSFT 60703 8213
35 B 2093243 AAPL 74855 814
37 S 6657449 AAPL 21216 4831
34 C 14492689
37 S 73105859 AAPL 12484 6550
33 S 99101411 AAPL 82472 7619
